<mujoco model="simple_differential_drive">
  <compiler angle="radian"/>

  <default>
    <default class="wheel">
      <geom type="cylinder" size="0.034 0.013" friction="2 0.005 0.0001" contype="1" conaffinity="1" mass="0.032"/>
      <joint type="hinge" frictionloss="0.001" damping="0.01" armature="0.01" limited="false"/>
    </default>
    <default class="idler_wheel">
      <geom type="cylinder" size="0.020 0.010" friction="2 0.005 0.0001" contype="1" conaffinity="1" mass="0.015"/>
      <joint type="hinge" frictionloss="0.001" damping="0.005" armature="0.001" limited="false"/>
    </default>
  </default>

  <worldbody>
    <body name="robot_body" pos="0 0 0.068">
      <joint type="free"/>
      <camera name="front_camera" mode="fixed" pos="0.05 0 -0.03" xyaxes="0 -1 0 0 0 1"/>

      <!-- Main body box -->
      <geom name="body_geom" type="box" size="0.05 0.05 0.05" pos="0 0 0" mass="1.0" rgba="1 0.5 0 1"/>
      <geom name="camera_indicator" type="box" size="0.002 0.015 0.010" pos="0.052 0 -0.03" rgba="0 0 0 1"/>

      <!-- Antennas -->
      <geom name="antenna_left" type="box" size="0.004 0.004 0.025" pos="0.01 -0.02 0.075" quat="0.9659258 0 -0.258819 0" rgba="0 0 0 1"/>
      <geom name="antenna_right" type="box" size="0.004 0.004 0.025" pos="0.01 0.02 0.075" quat="0.9659258 0 -0.258819 0" rgba="0 0 0 1"/>

      <!-- Left Gripper -->
      <geom name="gripper_left_base" type="box" size="0.007 0.007 0.015" pos="0.045 0.055 -0.005" rgba="0 0 0 1"/>
      <geom name="gripper_left_finger1" type="box" size="0.012 0.007 0.007" pos="0.057 0.055 -0.020" rgba="0 0 0 1"/>
      <geom name="gripper_left_finger2" type="box" size="0.012 0.007 0.007" pos="0.057 0.055 0.010" rgba="0 0 0 1"/>

      <!-- Right Gripper -->
      <geom name="gripper_right_base" type="box" size="0.007 0.007 0.015" pos="0.045 -0.055 -0.005" rgba="0 0 0 1"/>
      <geom name="gripper_right_finger1" type="box" size="0.012 0.007 0.007" pos="0.057 -0.055 -0.020" rgba="0 0 0 1"/>
      <geom name="gripper_right_finger2" type="box" size="0.012 0.007 0.007" pos="0.057 -0.055 0.010" rgba="0 0 0 1"/>

      <inertial pos="0 0 0" mass="1.0" diaginertia="0.001 0.001 0.001"/>

      <!-- Left wheel -->
      <body name="wheel_l" pos="0 0.065 -0.035">
        <joint class="wheel" name="wheel_l_throttle" axis="0 1 0"/>
        <geom class="wheel" quat="0.707107 0.707107 0 0" material="wheel_material"/>
      </body>

      <!-- Right wheel -->
      <body name="wheel_r" pos="0 -0.065 -0.035">
        <joint class="wheel" name="wheel_r_throttle" axis="0 1 0"/>
        <geom class="wheel" quat="0.707107 0.707107 0 0" material="wheel_material"/>
      </body>

      <!-- Front left idler wheel -->
      <body name="wheel_fl_idler" pos="0.055 0.055 -0.048">
        <joint class="idler_wheel" name="wheel_fl_idler_joint" axis="0 1 0"/>
        <geom class="idler_wheel" quat="0.707107 0.707107 0 0" material="wheel_material"/>
      </body>

      <!-- Front right idler wheel -->
      <body name="wheel_fr_idler" pos="0.055 -0.055 -0.048">
        <joint class="idler_wheel" name="wheel_fr_idler_joint" axis="0 1 0"/>
        <geom class="idler_wheel" quat="0.707107 0.707107 0 0" material="wheel_material"/>
      </body>

      <!-- Rear left idler wheel -->
      <body name="wheel_bl_idler" pos="-0.055 0.055 -0.048">
        <joint class="idler_wheel" name="wheel_bl_idler_joint" axis="0 1 0"/>
        <geom class="idler_wheel" quat="0.707107 0.707107 0 0" material="wheel_material"/>
      </body>

      <!-- Rear right idler wheel -->
      <body name="wheel_br_idler" pos="-0.055 -0.055 -0.048">
        <joint class="idler_wheel" name="wheel_br_idler_joint" axis="0 1 0"/>
        <geom class="idler_wheel" quat="0.707107 0.707107 0 0" material="wheel_material"/>
      </body>
    </body>
  </worldbody>

  <actuator>
    <velocity kv="100" gear="0.04" forcelimited="true" forcerange="-50 50" name="motor_l_wheel" joint="wheel_l_throttle"/>
    <velocity kv="100" gear="0.04" forcelimited="true" forcerange="-50 50" name="motor_r_wheel" joint="wheel_r_throttle"/>
  </actuator>
</mujoco>
